[2024-12-22T18:29:01.414+0000] {taskinstance.py:1083} INFO - Dependencies all met for <TaskInstance: user_processing.store_user manual__2024-12-22T18:28:56.905349+00:00 [queued]>
[2024-12-22T18:29:01.417+0000] {taskinstance.py:1083} INFO - Dependencies all met for <TaskInstance: user_processing.store_user manual__2024-12-22T18:28:56.905349+00:00 [queued]>
[2024-12-22T18:29:01.417+0000] {taskinstance.py:1279} INFO - 
--------------------------------------------------------------------------------
[2024-12-22T18:29:01.417+0000] {taskinstance.py:1280} INFO - Starting attempt 1 of 1
[2024-12-22T18:29:01.417+0000] {taskinstance.py:1281} INFO - 
--------------------------------------------------------------------------------
[2024-12-22T18:29:01.422+0000] {taskinstance.py:1300} INFO - Executing <Task(PythonOperator): store_user> on 2024-12-22 18:28:56.905349+00:00
[2024-12-22T18:29:01.424+0000] {standard_task_runner.py:55} INFO - Started process 78970 to run task
[2024-12-22T18:29:01.425+0000] {standard_task_runner.py:82} INFO - Running: ['***', 'tasks', 'run', 'user_processing', 'store_user', 'manual__2024-12-22T18:28:56.905349+00:00', '--job-id', '160', '--raw', '--subdir', 'DAGS_FOLDER/user_processing.py', '--cfg-path', '/tmp/tmpv2gr853l']
[2024-12-22T18:29:01.425+0000] {standard_task_runner.py:83} INFO - Job 160: Subtask store_user
[2024-12-22T18:29:01.448+0000] {task_command.py:388} INFO - Running <TaskInstance: user_processing.store_user manual__2024-12-22T18:28:56.905349+00:00 [running]> on host 44e036a430cc
[2024-12-22T18:29:01.472+0000] {taskinstance.py:1509} INFO - Exporting the following env vars:
AIRFLOW_CTX_DAG_OWNER=***
AIRFLOW_CTX_DAG_ID=user_processing
AIRFLOW_CTX_TASK_ID=store_user
AIRFLOW_CTX_EXECUTION_DATE=2024-12-22T18:28:56.905349+00:00
AIRFLOW_CTX_TRY_NUMBER=1
AIRFLOW_CTX_DAG_RUN_ID=manual__2024-12-22T18:28:56.905349+00:00
[2024-12-22T18:29:01.476+0000] {taskinstance.py:1768} ERROR - Task failed with exception
Traceback (most recent call last):
  File "/home/airflow/.local/lib/python3.7/site-packages/airflow/operators/python.py", line 175, in execute
    return_value = self.execute_callable()
  File "/home/airflow/.local/lib/python3.7/site-packages/airflow/operators/python.py", line 192, in execute_callable
    return self.python_callable(*self.op_args, **self.op_kwargs)
  File "/opt/airflow/dags/user_processing.py", line 37, in _store_user
    with open(f'/tmp/processed_user_{user["login"]["username"]}.csv', 'r') as f:
FileNotFoundError: [Errno 2] No such file or directory: '/tmp/processed_user_angrypanda356.csv'
[2024-12-22T18:29:01.479+0000] {taskinstance.py:1323} INFO - Marking task as FAILED. dag_id=user_processing, task_id=store_user, execution_date=20241222T182856, start_date=20241222T182901, end_date=20241222T182901
[2024-12-22T18:29:01.482+0000] {standard_task_runner.py:105} ERROR - Failed to execute job 160 for task store_user ([Errno 2] No such file or directory: '/tmp/processed_user_angrypanda356.csv'; 78970)
[2024-12-22T18:29:01.526+0000] {local_task_job.py:208} INFO - Task exited with return code 1
[2024-12-22T18:29:01.534+0000] {taskinstance.py:2578} INFO - 0 downstream tasks scheduled from follow-on schedule check
