[2024-12-22T18:33:02.110+0000] {taskinstance.py:1083} INFO - Dependencies all met for <TaskInstance: user_processing.store_user manual__2024-12-22T18:32:57.522616+00:00 [queued]>
[2024-12-22T18:33:02.113+0000] {taskinstance.py:1083} INFO - Dependencies all met for <TaskInstance: user_processing.store_user manual__2024-12-22T18:32:57.522616+00:00 [queued]>
[2024-12-22T18:33:02.113+0000] {taskinstance.py:1279} INFO - 
--------------------------------------------------------------------------------
[2024-12-22T18:33:02.113+0000] {taskinstance.py:1280} INFO - Starting attempt 1 of 1
[2024-12-22T18:33:02.113+0000] {taskinstance.py:1281} INFO - 
--------------------------------------------------------------------------------
[2024-12-22T18:33:02.118+0000] {taskinstance.py:1300} INFO - Executing <Task(PythonOperator): store_user> on 2024-12-22 18:32:57.522616+00:00
[2024-12-22T18:33:02.120+0000] {standard_task_runner.py:55} INFO - Started process 79334 to run task
[2024-12-22T18:33:02.121+0000] {standard_task_runner.py:82} INFO - Running: ['***', 'tasks', 'run', 'user_processing', 'store_user', 'manual__2024-12-22T18:32:57.522616+00:00', '--job-id', '165', '--raw', '--subdir', 'DAGS_FOLDER/user_processing.py', '--cfg-path', '/tmp/tmp078b9osd']
[2024-12-22T18:33:02.122+0000] {standard_task_runner.py:83} INFO - Job 165: Subtask store_user
[2024-12-22T18:33:02.143+0000] {task_command.py:388} INFO - Running <TaskInstance: user_processing.store_user manual__2024-12-22T18:32:57.522616+00:00 [running]> on host 44e036a430cc
[2024-12-22T18:33:02.167+0000] {taskinstance.py:1509} INFO - Exporting the following env vars:
AIRFLOW_CTX_DAG_OWNER=***
AIRFLOW_CTX_DAG_ID=user_processing
AIRFLOW_CTX_TASK_ID=store_user
AIRFLOW_CTX_EXECUTION_DATE=2024-12-22T18:32:57.522616+00:00
AIRFLOW_CTX_TRY_NUMBER=1
AIRFLOW_CTX_DAG_RUN_ID=manual__2024-12-22T18:32:57.522616+00:00
[2024-12-22T18:33:02.171+0000] {taskinstance.py:1768} ERROR - Task failed with exception
Traceback (most recent call last):
  File "/home/airflow/.local/lib/python3.7/site-packages/airflow/operators/python.py", line 175, in execute
    return_value = self.execute_callable()
  File "/home/airflow/.local/lib/python3.7/site-packages/airflow/operators/python.py", line 192, in execute_callable
    return self.python_callable(*self.op_args, **self.op_kwargs)
  File "/opt/airflow/dags/user_processing.py", line 40, in _store_user
    file=f
TypeError: copy_expert() got an unexpected keyword argument 'file'
[2024-12-22T18:33:02.174+0000] {taskinstance.py:1323} INFO - Marking task as FAILED. dag_id=user_processing, task_id=store_user, execution_date=20241222T183257, start_date=20241222T183302, end_date=20241222T183302
[2024-12-22T18:33:02.178+0000] {standard_task_runner.py:105} ERROR - Failed to execute job 165 for task store_user (copy_expert() got an unexpected keyword argument 'file'; 79334)
[2024-12-22T18:33:02.219+0000] {local_task_job.py:208} INFO - Task exited with return code 1
[2024-12-22T18:33:02.227+0000] {taskinstance.py:2578} INFO - 0 downstream tasks scheduled from follow-on schedule check
