[2024-12-11T05:52:52.703+0000] {taskinstance.py:1083} INFO - Dependencies all met for <TaskInstance: user_processing.is_api_available manual__2024-12-11T05:52:51.822630+00:00 [queued]>
[2024-12-11T05:52:52.706+0000] {taskinstance.py:1083} INFO - Dependencies all met for <TaskInstance: user_processing.is_api_available manual__2024-12-11T05:52:51.822630+00:00 [queued]>
[2024-12-11T05:52:52.707+0000] {taskinstance.py:1279} INFO - 
--------------------------------------------------------------------------------
[2024-12-11T05:52:52.707+0000] {taskinstance.py:1280} INFO - Starting attempt 1 of 1
[2024-12-11T05:52:52.707+0000] {taskinstance.py:1281} INFO - 
--------------------------------------------------------------------------------
[2024-12-11T05:52:52.714+0000] {taskinstance.py:1300} INFO - Executing <Task(HttpSensor): is_api_available> on 2024-12-11 05:52:51.822630+00:00
[2024-12-11T05:52:52.716+0000] {standard_task_runner.py:55} INFO - Started process 6985 to run task
[2024-12-11T05:52:52.718+0000] {standard_task_runner.py:82} INFO - Running: ['***', 'tasks', 'run', 'user_processing', 'is_api_available', 'manual__2024-12-11T05:52:51.822630+00:00', '--job-id', '49', '--raw', '--subdir', 'DAGS_FOLDER/user_processing.py', '--cfg-path', '/tmp/tmprqo4nlp4']
[2024-12-11T05:52:52.718+0000] {standard_task_runner.py:83} INFO - Job 49: Subtask is_api_available
[2024-12-11T05:52:52.745+0000] {task_command.py:388} INFO - Running <TaskInstance: user_processing.is_api_available manual__2024-12-11T05:52:51.822630+00:00 [running]> on host 44e036a430cc
[2024-12-11T05:52:52.774+0000] {taskinstance.py:1509} INFO - Exporting the following env vars:
AIRFLOW_CTX_DAG_OWNER=***
AIRFLOW_CTX_DAG_ID=user_processing
AIRFLOW_CTX_TASK_ID=is_api_available
AIRFLOW_CTX_EXECUTION_DATE=2024-12-11T05:52:51.822630+00:00
AIRFLOW_CTX_TRY_NUMBER=1
AIRFLOW_CTX_DAG_RUN_ID=manual__2024-12-11T05:52:51.822630+00:00
[2024-12-11T05:52:52.775+0000] {http.py:122} INFO - Poking: https://randomuser.me/
[2024-12-11T05:52:52.778+0000] {base.py:73} INFO - Using connection ID 'user_api' for task execution.
[2024-12-11T05:52:52.828+0000] {http.py:208} WARNING - HTTPConnectionPool(host='https', port=80): Max retries exceeded with url: //randomuser.me/ (Caused by NewConnectionError('<urllib3.connection.HTTPConnection object at 0xffff9f0f7fd0>: Failed to establish a new connection: [Errno -2] Name or service not known')) Tenacity will retry to execute the operation
[2024-12-11T05:52:52.829+0000] {taskinstance.py:1768} ERROR - Task failed with exception
Traceback (most recent call last):
  File "/home/airflow/.local/lib/python3.7/site-packages/urllib3/connection.py", line 175, in _new_conn
    (self._dns_host, self.port), self.timeout, **extra_kw
  File "/home/airflow/.local/lib/python3.7/site-packages/urllib3/util/connection.py", line 72, in create_connection
    for res in socket.getaddrinfo(host, port, family, socket.SOCK_STREAM):
  File "/usr/local/lib/python3.7/socket.py", line 752, in getaddrinfo
    for res in _socket.getaddrinfo(host, port, family, type, proto, flags):
socket.gaierror: [Errno -2] Name or service not known

During handling of the above exception, another exception occurred:

Traceback (most recent call last):
  File "/home/airflow/.local/lib/python3.7/site-packages/urllib3/connectionpool.py", line 710, in urlopen
    chunked=chunked,
  File "/home/airflow/.local/lib/python3.7/site-packages/urllib3/connectionpool.py", line 398, in _make_request
    conn.request(method, url, **httplib_request_kw)
  File "/home/airflow/.local/lib/python3.7/site-packages/urllib3/connection.py", line 239, in request
    super(HTTPConnection, self).request(method, url, body=body, headers=headers)
  File "/usr/local/lib/python3.7/http/client.py", line 1281, in request
    self._send_request(method, url, body, headers, encode_chunked)
  File "/usr/local/lib/python3.7/http/client.py", line 1327, in _send_request
    self.endheaders(body, encode_chunked=encode_chunked)
  File "/usr/local/lib/python3.7/http/client.py", line 1276, in endheaders
    self._send_output(message_body, encode_chunked=encode_chunked)
  File "/usr/local/lib/python3.7/http/client.py", line 1036, in _send_output
    self.send(msg)
  File "/usr/local/lib/python3.7/http/client.py", line 976, in send
    self.connect()
  File "/home/airflow/.local/lib/python3.7/site-packages/urllib3/connection.py", line 205, in connect
    conn = self._new_conn()
  File "/home/airflow/.local/lib/python3.7/site-packages/urllib3/connection.py", line 187, in _new_conn
    self, "Failed to establish a new connection: %s" % e
urllib3.exceptions.NewConnectionError: <urllib3.connection.HTTPConnection object at 0xffff9f0f7fd0>: Failed to establish a new connection: [Errno -2] Name or service not known

During handling of the above exception, another exception occurred:

Traceback (most recent call last):
  File "/home/airflow/.local/lib/python3.7/site-packages/requests/adapters.py", line 499, in send
    timeout=timeout,
  File "/home/airflow/.local/lib/python3.7/site-packages/urllib3/connectionpool.py", line 788, in urlopen
    method, url, error=e, _pool=self, _stacktrace=sys.exc_info()[2]
  File "/home/airflow/.local/lib/python3.7/site-packages/urllib3/util/retry.py", line 592, in increment
    raise MaxRetryError(_pool, url, error or ResponseError(cause))
urllib3.exceptions.MaxRetryError: HTTPConnectionPool(host='https', port=80): Max retries exceeded with url: //randomuser.me/ (Caused by NewConnectionError('<urllib3.connection.HTTPConnection object at 0xffff9f0f7fd0>: Failed to establish a new connection: [Errno -2] Name or service not known'))

During handling of the above exception, another exception occurred:

Traceback (most recent call last):
  File "/home/airflow/.local/lib/python3.7/site-packages/airflow/sensors/base.py", line 199, in execute
    poke_return = self.poke(context)
  File "/home/airflow/.local/lib/python3.7/site-packages/airflow/providers/http/sensors/http.py", line 128, in poke
    extra_options=self.extra_options,
  File "/home/airflow/.local/lib/python3.7/site-packages/airflow/providers/http/hooks/http.py", line 151, in run
    return self.run_and_check(session, prepped_request, extra_options)
  File "/home/airflow/.local/lib/python3.7/site-packages/airflow/providers/http/hooks/http.py", line 209, in run_and_check
    raise ex
  File "/home/airflow/.local/lib/python3.7/site-packages/airflow/providers/http/hooks/http.py", line 201, in run_and_check
    response = session.send(prepped_request, **send_kwargs)
  File "/home/airflow/.local/lib/python3.7/site-packages/requests/sessions.py", line 701, in send
    r = adapter.send(request, **kwargs)
  File "/home/airflow/.local/lib/python3.7/site-packages/requests/adapters.py", line 565, in send
    raise ConnectionError(e, request=request)
requests.exceptions.ConnectionError: HTTPConnectionPool(host='https', port=80): Max retries exceeded with url: //randomuser.me/ (Caused by NewConnectionError('<urllib3.connection.HTTPConnection object at 0xffff9f0f7fd0>: Failed to establish a new connection: [Errno -2] Name or service not known'))
[2024-12-11T05:52:52.835+0000] {taskinstance.py:1323} INFO - Marking task as FAILED. dag_id=user_processing, task_id=is_api_available, execution_date=20241211T055251, start_date=20241211T055252, end_date=20241211T055252
[2024-12-11T05:52:52.840+0000] {standard_task_runner.py:105} ERROR - Failed to execute job 49 for task is_api_available (HTTPConnectionPool(host='https', port=80): Max retries exceeded with url: //randomuser.me/ (Caused by NewConnectionError('<urllib3.connection.HTTPConnection object at 0xffff9f0f7fd0>: Failed to establish a new connection: [Errno -2] Name or service not known')); 6985)
[2024-12-11T05:52:52.858+0000] {local_task_job.py:208} INFO - Task exited with return code 1
[2024-12-11T05:52:52.865+0000] {taskinstance.py:2578} INFO - 0 downstream tasks scheduled from follow-on schedule check
