[2024-12-15T01:24:33.282+0000] {taskinstance.py:1083} INFO - Dependencies all met for <TaskInstance: user_processing.extract_user_data scheduled__2024-12-12T00:00:00+00:00 [queued]>
[2024-12-15T01:24:33.296+0000] {taskinstance.py:1083} INFO - Dependencies all met for <TaskInstance: user_processing.extract_user_data scheduled__2024-12-12T00:00:00+00:00 [queued]>
[2024-12-15T01:24:33.296+0000] {taskinstance.py:1279} INFO - 
--------------------------------------------------------------------------------
[2024-12-15T01:24:33.296+0000] {taskinstance.py:1280} INFO - Starting attempt 1 of 1
[2024-12-15T01:24:33.296+0000] {taskinstance.py:1281} INFO - 
--------------------------------------------------------------------------------
[2024-12-15T01:24:33.352+0000] {taskinstance.py:1300} INFO - Executing <Task(SimpleHttpOperator): extract_user_data> on 2024-12-12 00:00:00+00:00
[2024-12-15T01:24:33.375+0000] {standard_task_runner.py:55} INFO - Started process 82 to run task
[2024-12-15T01:24:33.378+0000] {standard_task_runner.py:82} INFO - Running: ['***', 'tasks', 'run', 'user_processing', 'extract_user_data', 'scheduled__2024-12-12T00:00:00+00:00', '--job-id', '63', '--raw', '--subdir', 'DAGS_FOLDER/user_processing.py', '--cfg-path', '/tmp/tmp635lrdzu']
[2024-12-15T01:24:33.381+0000] {standard_task_runner.py:83} INFO - Job 63: Subtask extract_user_data
[2024-12-15T01:24:33.492+0000] {task_command.py:388} INFO - Running <TaskInstance: user_processing.extract_user_data scheduled__2024-12-12T00:00:00+00:00 [running]> on host 44e036a430cc
[2024-12-15T01:24:33.595+0000] {taskinstance.py:1509} INFO - Exporting the following env vars:
AIRFLOW_CTX_DAG_OWNER=***
AIRFLOW_CTX_DAG_ID=user_processing
AIRFLOW_CTX_TASK_ID=extract_user_data
AIRFLOW_CTX_EXECUTION_DATE=2024-12-12T00:00:00+00:00
AIRFLOW_CTX_TRY_NUMBER=1
AIRFLOW_CTX_DAG_RUN_ID=scheduled__2024-12-12T00:00:00+00:00
[2024-12-15T01:24:33.597+0000] {http.py:123} INFO - Calling HTTP method
[2024-12-15T01:24:33.608+0000] {base.py:73} INFO - Using connection ID 'user_api' for task execution.
[2024-12-15T01:24:33.651+0000] {http.py:208} WARNING - HTTPConnectionPool(host='https', port=80): Max retries exceeded with url: //randomuser.me/ (Caused by NewConnectionError('<urllib3.connection.HTTPConnection object at 0xffff69e81e10>: Failed to establish a new connection: [Errno -2] Name or service not known')) Tenacity will retry to execute the operation
[2024-12-15T01:24:33.653+0000] {taskinstance.py:1768} ERROR - Task failed with exception
Traceback (most recent call last):
  File "/home/airflow/.local/lib/python3.7/site-packages/urllib3/connection.py", line 175, in _new_conn
    (self._dns_host, self.port), self.timeout, **extra_kw
  File "/home/airflow/.local/lib/python3.7/site-packages/urllib3/util/connection.py", line 72, in create_connection
    for res in socket.getaddrinfo(host, port, family, socket.SOCK_STREAM):
  File "/usr/local/lib/python3.7/socket.py", line 752, in getaddrinfo
    for res in _socket.getaddrinfo(host, port, family, type, proto, flags):
socket.gaierror: [Errno -2] Name or service not known

During handling of the above exception, another exception occurred:

Traceback (most recent call last):
  File "/home/airflow/.local/lib/python3.7/site-packages/urllib3/connectionpool.py", line 710, in urlopen
    chunked=chunked,
  File "/home/airflow/.local/lib/python3.7/site-packages/urllib3/connectionpool.py", line 398, in _make_request
    conn.request(method, url, **httplib_request_kw)
  File "/home/airflow/.local/lib/python3.7/site-packages/urllib3/connection.py", line 239, in request
    super(HTTPConnection, self).request(method, url, body=body, headers=headers)
  File "/usr/local/lib/python3.7/http/client.py", line 1281, in request
    self._send_request(method, url, body, headers, encode_chunked)
  File "/usr/local/lib/python3.7/http/client.py", line 1327, in _send_request
    self.endheaders(body, encode_chunked=encode_chunked)
  File "/usr/local/lib/python3.7/http/client.py", line 1276, in endheaders
    self._send_output(message_body, encode_chunked=encode_chunked)
  File "/usr/local/lib/python3.7/http/client.py", line 1036, in _send_output
    self.send(msg)
  File "/usr/local/lib/python3.7/http/client.py", line 976, in send
    self.connect()
  File "/home/airflow/.local/lib/python3.7/site-packages/urllib3/connection.py", line 205, in connect
    conn = self._new_conn()
  File "/home/airflow/.local/lib/python3.7/site-packages/urllib3/connection.py", line 187, in _new_conn
    self, "Failed to establish a new connection: %s" % e
urllib3.exceptions.NewConnectionError: <urllib3.connection.HTTPConnection object at 0xffff69e81e10>: Failed to establish a new connection: [Errno -2] Name or service not known

During handling of the above exception, another exception occurred:

Traceback (most recent call last):
  File "/home/airflow/.local/lib/python3.7/site-packages/requests/adapters.py", line 499, in send
    timeout=timeout,
  File "/home/airflow/.local/lib/python3.7/site-packages/urllib3/connectionpool.py", line 788, in urlopen
    method, url, error=e, _pool=self, _stacktrace=sys.exc_info()[2]
  File "/home/airflow/.local/lib/python3.7/site-packages/urllib3/util/retry.py", line 592, in increment
    raise MaxRetryError(_pool, url, error or ResponseError(cause))
urllib3.exceptions.MaxRetryError: HTTPConnectionPool(host='https', port=80): Max retries exceeded with url: //randomuser.me/ (Caused by NewConnectionError('<urllib3.connection.HTTPConnection object at 0xffff69e81e10>: Failed to establish a new connection: [Errno -2] Name or service not known'))

During handling of the above exception, another exception occurred:

Traceback (most recent call last):
  File "/home/airflow/.local/lib/python3.7/site-packages/airflow/providers/http/operators/http.py", line 125, in execute
    response = http.run(self.endpoint, self.data, self.headers, self.extra_options)
  File "/home/airflow/.local/lib/python3.7/site-packages/airflow/providers/http/hooks/http.py", line 151, in run
    return self.run_and_check(session, prepped_request, extra_options)
  File "/home/airflow/.local/lib/python3.7/site-packages/airflow/providers/http/hooks/http.py", line 209, in run_and_check
    raise ex
  File "/home/airflow/.local/lib/python3.7/site-packages/airflow/providers/http/hooks/http.py", line 201, in run_and_check
    response = session.send(prepped_request, **send_kwargs)
  File "/home/airflow/.local/lib/python3.7/site-packages/requests/sessions.py", line 701, in send
    r = adapter.send(request, **kwargs)
  File "/home/airflow/.local/lib/python3.7/site-packages/requests/adapters.py", line 565, in send
    raise ConnectionError(e, request=request)
requests.exceptions.ConnectionError: HTTPConnectionPool(host='https', port=80): Max retries exceeded with url: //randomuser.me/ (Caused by NewConnectionError('<urllib3.connection.HTTPConnection object at 0xffff69e81e10>: Failed to establish a new connection: [Errno -2] Name or service not known'))
[2024-12-15T01:24:33.675+0000] {taskinstance.py:1323} INFO - Marking task as FAILED. dag_id=user_processing, task_id=extract_user_data, execution_date=20241212T000000, start_date=20241215T012433, end_date=20241215T012433
[2024-12-15T01:24:33.693+0000] {standard_task_runner.py:105} ERROR - Failed to execute job 63 for task extract_user_data (HTTPConnectionPool(host='https', port=80): Max retries exceeded with url: //randomuser.me/ (Caused by NewConnectionError('<urllib3.connection.HTTPConnection object at 0xffff69e81e10>: Failed to establish a new connection: [Errno -2] Name or service not known')); 82)
[2024-12-15T01:24:33.728+0000] {local_task_job.py:208} INFO - Task exited with return code 1
[2024-12-15T01:24:33.747+0000] {taskinstance.py:2578} INFO - 0 downstream tasks scheduled from follow-on schedule check
