[2025-04-25T04:41:20.942+0000] {taskinstance.py:1083} INFO - Dependencies all met for <TaskInstance: user_processing.is_api_available manual__2025-04-25T04:41:19.332833+00:00 [queued]>
[2025-04-25T04:41:20.945+0000] {taskinstance.py:1083} INFO - Dependencies all met for <TaskInstance: user_processing.is_api_available manual__2025-04-25T04:41:19.332833+00:00 [queued]>
[2025-04-25T04:41:20.945+0000] {taskinstance.py:1279} INFO - 
--------------------------------------------------------------------------------
[2025-04-25T04:41:20.945+0000] {taskinstance.py:1280} INFO - Starting attempt 1 of 1
[2025-04-25T04:41:20.945+0000] {taskinstance.py:1281} INFO - 
--------------------------------------------------------------------------------
[2025-04-25T04:41:20.950+0000] {taskinstance.py:1300} INFO - Executing <Task(HttpSensor): is_api_available> on 2025-04-25 04:41:19.332833+00:00
[2025-04-25T04:41:20.952+0000] {standard_task_runner.py:55} INFO - Started process 7831 to run task
[2025-04-25T04:41:20.954+0000] {standard_task_runner.py:82} INFO - Running: ['***', 'tasks', 'run', 'user_processing', 'is_api_available', 'manual__2025-04-25T04:41:19.332833+00:00', '--job-id', '13', '--raw', '--subdir', 'DAGS_FOLDER/user_processing.py', '--cfg-path', '/tmp/tmpdkj_2mq3']
[2025-04-25T04:41:20.954+0000] {standard_task_runner.py:83} INFO - Job 13: Subtask is_api_available
[2025-04-25T04:41:20.976+0000] {task_command.py:388} INFO - Running <TaskInstance: user_processing.is_api_available manual__2025-04-25T04:41:19.332833+00:00 [running]> on host b08efc87d46b
[2025-04-25T04:41:21.000+0000] {taskinstance.py:1509} INFO - Exporting the following env vars:
AIRFLOW_CTX_DAG_OWNER=***
AIRFLOW_CTX_DAG_ID=user_processing
AIRFLOW_CTX_TASK_ID=is_api_available
AIRFLOW_CTX_EXECUTION_DATE=2025-04-25T04:41:19.332833+00:00
AIRFLOW_CTX_TRY_NUMBER=1
AIRFLOW_CTX_DAG_RUN_ID=manual__2025-04-25T04:41:19.332833+00:00
[2025-04-25T04:41:21.001+0000] {http.py:122} INFO - Poking: api/
[2025-04-25T04:41:21.007+0000] {taskinstance.py:1768} ERROR - Task failed with exception
Traceback (most recent call last):
  File "/home/airflow/.local/lib/python3.7/site-packages/airflow/sensors/base.py", line 199, in execute
    poke_return = self.poke(context)
  File "/home/airflow/.local/lib/python3.7/site-packages/airflow/providers/http/sensors/http.py", line 137, in poke
    raise exc
  File "/home/airflow/.local/lib/python3.7/site-packages/airflow/providers/http/sensors/http.py", line 128, in poke
    extra_options=self.extra_options,
  File "/home/airflow/.local/lib/python3.7/site-packages/airflow/providers/http/hooks/http.py", line 130, in run
    session = self.get_conn(headers)
  File "/home/airflow/.local/lib/python3.7/site-packages/airflow/providers/http/hooks/http.py", line 84, in get_conn
    conn = self.get_connection(self.http_conn_id)
  File "/home/airflow/.local/lib/python3.7/site-packages/airflow/hooks/base.py", line 72, in get_connection
    conn = Connection.get_connection_from_secrets(conn_id)
  File "/home/airflow/.local/lib/python3.7/site-packages/airflow/models/connection.py", line 435, in get_connection_from_secrets
    raise AirflowNotFoundException(f"The conn_id `{conn_id}` isn't defined")
airflow.exceptions.AirflowNotFoundException: The conn_id `user_api` isn't defined
[2025-04-25T04:41:21.008+0000] {taskinstance.py:1323} INFO - Marking task as FAILED. dag_id=user_processing, task_id=is_api_available, execution_date=20250425T044119, start_date=20250425T044120, end_date=20250425T044121
[2025-04-25T04:41:21.012+0000] {standard_task_runner.py:105} ERROR - Failed to execute job 13 for task is_api_available (The conn_id `user_api` isn't defined; 7831)
[2025-04-25T04:41:21.054+0000] {local_task_job.py:208} INFO - Task exited with return code 1
[2025-04-25T04:41:21.067+0000] {taskinstance.py:2578} INFO - 0 downstream tasks scheduled from follow-on schedule check
