[2025-04-25T04:08:05.319+0000] {taskinstance.py:1083} INFO - Dependencies all met for <TaskInstance: user_processing.create_table manual__2025-04-25T04:08:04.568130+00:00 [queued]>
[2025-04-25T04:08:05.323+0000] {taskinstance.py:1083} INFO - Dependencies all met for <TaskInstance: user_processing.create_table manual__2025-04-25T04:08:04.568130+00:00 [queued]>
[2025-04-25T04:08:05.323+0000] {taskinstance.py:1279} INFO - 
--------------------------------------------------------------------------------
[2025-04-25T04:08:05.323+0000] {taskinstance.py:1280} INFO - Starting attempt 1 of 1
[2025-04-25T04:08:05.323+0000] {taskinstance.py:1281} INFO - 
--------------------------------------------------------------------------------
[2025-04-25T04:08:05.328+0000] {taskinstance.py:1300} INFO - Executing <Task(PostgresOperator): create_table> on 2025-04-25 04:08:04.568130+00:00
[2025-04-25T04:08:05.331+0000] {standard_task_runner.py:55} INFO - Started process 4892 to run task
[2025-04-25T04:08:05.332+0000] {standard_task_runner.py:82} INFO - Running: ['***', 'tasks', 'run', 'user_processing', 'create_table', 'manual__2025-04-25T04:08:04.568130+00:00', '--job-id', '5', '--raw', '--subdir', 'DAGS_FOLDER/user_processing.py', '--cfg-path', '/tmp/tmp0yhpwgwn']
[2025-04-25T04:08:05.333+0000] {standard_task_runner.py:83} INFO - Job 5: Subtask create_table
[2025-04-25T04:08:05.354+0000] {task_command.py:388} INFO - Running <TaskInstance: user_processing.create_table manual__2025-04-25T04:08:04.568130+00:00 [running]> on host b08efc87d46b
[2025-04-25T04:08:05.377+0000] {taskinstance.py:1509} INFO - Exporting the following env vars:
AIRFLOW_CTX_DAG_OWNER=***
AIRFLOW_CTX_DAG_ID=user_processing
AIRFLOW_CTX_TASK_ID=create_table
AIRFLOW_CTX_EXECUTION_DATE=2025-04-25T04:08:04.568130+00:00
AIRFLOW_CTX_TRY_NUMBER=1
AIRFLOW_CTX_DAG_RUN_ID=manual__2025-04-25T04:08:04.568130+00:00
[2025-04-25T04:08:05.378+0000] {sql.py:254} INFO - Executing: CREATE TABLE IF NOT EXISTS users (
            firstname TEXT NOT NULL,
            lastname TEXT NOT NULL,
            country TEXT NOT NULL,
            username TEXT NOT NULL,
            password TEXT NOT NULL,
            email TEXT NOT NULL);
[2025-04-25T04:08:05.384+0000] {taskinstance.py:1768} ERROR - Task failed with exception
Traceback (most recent call last):
  File "/home/airflow/.local/lib/python3.7/site-packages/airflow/providers/common/sql/operators/sql.py", line 255, in execute
    hook = self.get_db_hook()
  File "/home/airflow/.local/lib/python3.7/site-packages/airflow/providers/common/sql/operators/sql.py", line 179, in get_db_hook
    return self._hook
  File "/home/airflow/.local/lib/python3.7/site-packages/cached_property.py", line 36, in __get__
    value = obj.__dict__[self.func.__name__] = self.func(obj)
  File "/home/airflow/.local/lib/python3.7/site-packages/airflow/providers/common/sql/operators/sql.py", line 141, in _hook
    conn = BaseHook.get_connection(self.conn_id)
  File "/home/airflow/.local/lib/python3.7/site-packages/airflow/hooks/base.py", line 72, in get_connection
    conn = Connection.get_connection_from_secrets(conn_id)
  File "/home/airflow/.local/lib/python3.7/site-packages/airflow/models/connection.py", line 435, in get_connection_from_secrets
    raise AirflowNotFoundException(f"The conn_id `{conn_id}` isn't defined")
airflow.exceptions.AirflowNotFoundException: The conn_id `postgres` isn't defined
[2025-04-25T04:08:05.385+0000] {taskinstance.py:1323} INFO - Marking task as FAILED. dag_id=user_processing, task_id=create_table, execution_date=20250425T040804, start_date=20250425T040805, end_date=20250425T040805
[2025-04-25T04:08:05.389+0000] {standard_task_runner.py:105} ERROR - Failed to execute job 5 for task create_table (The conn_id `postgres` isn't defined; 4892)
[2025-04-25T04:08:05.434+0000] {local_task_job.py:208} INFO - Task exited with return code 1
[2025-04-25T04:08:05.445+0000] {taskinstance.py:2578} INFO - 0 downstream tasks scheduled from follow-on schedule check
