[2024-12-21T20:07:25.624+0000] {taskinstance.py:1083} INFO - Dependencies all met for <TaskInstance: user_processing.process_user manual__2024-12-21T20:07:21.889582+00:00 [queued]>
[2024-12-21T20:07:25.627+0000] {taskinstance.py:1083} INFO - Dependencies all met for <TaskInstance: user_processing.process_user manual__2024-12-21T20:07:21.889582+00:00 [queued]>
[2024-12-21T20:07:25.627+0000] {taskinstance.py:1279} INFO - 
--------------------------------------------------------------------------------
[2024-12-21T20:07:25.627+0000] {taskinstance.py:1280} INFO - Starting attempt 1 of 1
[2024-12-21T20:07:25.627+0000] {taskinstance.py:1281} INFO - 
--------------------------------------------------------------------------------
[2024-12-21T20:07:25.632+0000] {taskinstance.py:1300} INFO - Executing <Task(PythonOperator): process_user> on 2024-12-21 20:07:21.889582+00:00
[2024-12-21T20:07:25.634+0000] {standard_task_runner.py:55} INFO - Started process 66423 to run task
[2024-12-21T20:07:25.636+0000] {standard_task_runner.py:82} INFO - Running: ['***', 'tasks', 'run', 'user_processing', 'process_user', 'manual__2024-12-21T20:07:21.889582+00:00', '--job-id', '130', '--raw', '--subdir', 'DAGS_FOLDER/user_processing.py', '--cfg-path', '/tmp/tmp0m9wn3t7']
[2024-12-21T20:07:25.636+0000] {standard_task_runner.py:83} INFO - Job 130: Subtask process_user
[2024-12-21T20:07:25.658+0000] {task_command.py:388} INFO - Running <TaskInstance: user_processing.process_user manual__2024-12-21T20:07:21.889582+00:00 [running]> on host 44e036a430cc
[2024-12-21T20:07:25.681+0000] {taskinstance.py:1509} INFO - Exporting the following env vars:
AIRFLOW_CTX_DAG_OWNER=***
AIRFLOW_CTX_DAG_ID=user_processing
AIRFLOW_CTX_TASK_ID=process_user
AIRFLOW_CTX_EXECUTION_DATE=2024-12-21T20:07:21.889582+00:00
AIRFLOW_CTX_TRY_NUMBER=1
AIRFLOW_CTX_DAG_RUN_ID=manual__2024-12-21T20:07:21.889582+00:00
[2024-12-21T20:07:25.688+0000] {taskinstance.py:1768} ERROR - Task failed with exception
Traceback (most recent call last):
  File "/home/airflow/.local/lib/python3.7/site-packages/airflow/operators/python.py", line 175, in execute
    return_value = self.execute_callable()
  File "/home/airflow/.local/lib/python3.7/site-packages/airflow/operators/python.py", line 192, in execute_callable
    return self.python_callable(*self.op_args, **self.op_kwargs)
  File "/opt/airflow/dags/user_processing.py", line 16, in _process_user
    raise AirflowException("No user data found from extract_user_data task!")
airflow.exceptions.AirflowException: No user data found from extract_user_data task!
[2024-12-21T20:07:25.690+0000] {taskinstance.py:1323} INFO - Marking task as FAILED. dag_id=user_processing, task_id=process_user, execution_date=20241221T200721, start_date=20241221T200725, end_date=20241221T200725
[2024-12-21T20:07:25.693+0000] {standard_task_runner.py:105} ERROR - Failed to execute job 130 for task process_user (No user data found from extract_user_data task!; 66423)
[2024-12-21T20:07:25.735+0000] {local_task_job.py:208} INFO - Task exited with return code 1
[2024-12-21T20:07:25.746+0000] {taskinstance.py:2578} INFO - 0 downstream tasks scheduled from follow-on schedule check
